WARNING:cassandra.cluster:Cluster.__init__ called with contact_points specified, but no load_balancing_policy. In the next major version, this will raise an error; please specify a load-balancing policy. (contact_points = ['localhost'], lbp = None)
WARNING:cassandra.cluster:[control connection] Error connecting to ::1:9042:
Traceback (most recent call last):
  File "cassandra/cluster.py", line 3577, in cassandra.cluster.ControlConnection._reconnect_internal
  File "cassandra/cluster.py", line 3599, in cassandra.cluster.ControlConnection._try_connect
  File "cassandra/cluster.py", line 1670, in cassandra.cluster.Cluster.connection_factory
  File "cassandra/connection.py", line 846, in cassandra.connection.Connection.factory
  File "/home/pinil/.local/lib/python3.12/site-packages/cassandra/io/libevreactor.py", line 267, in __init__
    self._connect_socket()
  File "cassandra/connection.py", line 951, in cassandra.connection.Connection._connect_socket
ConnectionRefusedError: [Errno 111] Tried connecting to [('::1', 9042, 0, 0)]. Last error: Connection refused
WARNING:cassandra.cluster:Downgrading core protocol version from 66 to 65 for 127.0.0.1:9042. To avoid this, it is best practice to explicitly set Cluster(protocol_version) to the version supported by your cluster. http://datastax.github.io/python-driver/api/cassandra/cluster.html#cassandra.cluster.Cluster.protocol_version
WARNING:cassandra.cluster:Downgrading core protocol version from 65 to 5 for 127.0.0.1:9042. To avoid this, it is best practice to explicitly set Cluster(protocol_version) to the version supported by your cluster. http://datastax.github.io/python-driver/api/cassandra/cluster.html#cassandra.cluster.Cluster.protocol_version
ERROR:root:Exception while sending command.
Traceback (most recent call last):
  File "/home/pinil/.local/lib/python3.12/site-packages/py4j/clientserver.py", line 511, in send_command
    answer = smart_decode(self.stream.readline()[:-1])
                          ^^^^^^^^^^^^^^^^^^^^^^
RuntimeError: reentrant call inside <_io.BufferedReader name=4>

During handling of the above exception, another exception occurred:

Traceback (most recent call last):
  File "/home/pinil/.local/lib/python3.12/site-packages/py4j/java_gateway.py", line 1038, in send_command
    response = connection.send_command(command)
               ^^^^^^^^^^^^^^^^^^^^^^^^^^^^^^^^
  File "/home/pinil/.local/lib/python3.12/site-packages/py4j/clientserver.py", line 539, in send_command
    raise Py4JNetworkError(
py4j.protocol.Py4JNetworkError: Error while sending or receiving
ERROR:root:Exception while sending command.
Traceback (most recent call last):
  File "/home/pinil/.local/lib/python3.12/site-packages/py4j/clientserver.py", line 511, in send_command
    answer = smart_decode(self.stream.readline()[:-1])
                          ^^^^^^^^^^^^^^^^^^^^^^
  File "/usr/lib64/python3.12/socket.py", line 720, in readinto
    return self._sock.recv_into(b)
           ^^^^^^^^^^^^^^^^^^^^^^^
  File "/home/pinil/.local/lib/python3.12/site-packages/pyspark/context.py", line 381, in signal_handler
    self.cancelAllJobs()
  File "/home/pinil/.local/lib/python3.12/site-packages/pyspark/context.py", line 2446, in cancelAllJobs
    self._jsc.sc().cancelAllJobs()
    ^^^^^^^^^^^^^^
  File "/home/pinil/.local/lib/python3.12/site-packages/py4j/java_gateway.py", line 1322, in __call__
    return_value = get_return_value(
                   ^^^^^^^^^^^^^^^^^
  File "/home/pinil/.local/lib/python3.12/site-packages/pyspark/errors/exceptions/captured.py", line 179, in deco
    return f(*a, **kw)
           ^^^^^^^^^^^
  File "/home/pinil/.local/lib/python3.12/site-packages/py4j/protocol.py", line 334, in get_return_value
    raise Py4JError(
py4j.protocol.Py4JError: An error occurred while calling o20.sc

During handling of the above exception, another exception occurred:

Traceback (most recent call last):
  File "/home/pinil/.local/lib/python3.12/site-packages/py4j/java_gateway.py", line 1038, in send_command
    response = connection.send_command(command)
               ^^^^^^^^^^^^^^^^^^^^^^^^^^^^^^^^
  File "/home/pinil/.local/lib/python3.12/site-packages/py4j/clientserver.py", line 539, in send_command
    raise Py4JNetworkError(
py4j.protocol.Py4JNetworkError: Error while sending or receiving
